<?xml version="1.0" ?><!-- =================================================================================== --><!-- |    This document was autogenerated by xacro from /home/lpep/ros2ws/install/lp_neural_swarm/share/lp_neural_swarm/urdf/differential_drive_cam_lidar_fisheyes.xacro | --><!-- |    EDITING THIS FILE BY HAND IS NOT RECOMMENDED                                 | --><!-- =================================================================================== --><robot name="fourWD"><!-- Defining the colors used in this robot --><material name="Black"><color rgba="0.0 0.0 0.0 1.0"/></material><material name="Red"><color rgba="1.0 0.0 0.0 1.0"/></material><material name="White"><color rgba="1.0 1.0 1.0 1.0"/></material><material name="Yellow"><color rgba="0.0 1.0 1.0 1.0"/></material><material name="Blue"><color rgba="0.0 0.0 0.8 1.0"/></material><!-- in kg--><!-- in kg--><!-- BASE-LINK --><!--Actual body/chassis of the robot--><link name="base_link"><inertial><mass value="0.7"/><origin xyz="0 0 0"/><inertia ixx="0.001698958333333333" ixy="0" ixz="0" iyy="0.003295833333333333" iyz="0" izz="0.004049791666666666"/></inertial><visual><origin rpy="0 0 0" xyz="0 0 0"/><geometry><box size="0.22 0.145 0.09"/></geometry><material name="White"/></visual><collision><origin rpy="0 0 0 " xyz="0 0 0"/><geometry><box size="0.22 0.145 0.09"/></geometry></collision></link><gazebo reference="base_link"><material>Gazebo/White</material><turnGravityOff>false</turnGravityOff></gazebo><!-- caster wheel --><link name="caster_link"><collision><origin rpy="0 0 0" xyz="0 0 0"/><geometry><sphere radius="0.032"/></geometry></collision><visual><origin rpy="0 0 0" xyz="0 0 0"/><geometry><sphere radius="0.032"/></geometry><material name="Blue"/></visual></link><gazebo reference="caster_link"><mu1 value="0.0"/><mu2 value="0.0"/><material>Gazebo/Blue</material><turnGravityOff>false</turnGravityOff></gazebo><joint name="caster_joint" type="fixed"><origin rpy="0 0 0" xyz="0.11 0 -0.045"/><parent link="base_link"/><child link="caster_link"/></joint><!-- RIGHT WHEEL --><link name="back_right_wheel"><visual><origin rpy="0 1.5707963267948966 1.5707963267948966" xyz="0 0 0"/><geometry><cylinder length="0.025" radius="0.032"/></geometry><material name="DarkGray"/></visual><collision><origin rpy="0 1.5707963267948966 1.5707963267948966" xyz="0 0 0"/><geometry><cylinder length="0.025" radius="0.032"/></geometry></collision><inertial><mass value="0.03"/><origin rpy="0 1.5707963267948966 1.5707963267948966" xyz="0 0 0"/><inertia ixx="9.2425e-06" ixy="0" ixz="0" iyy="9.2425e-06" iyz="0" izz="1.5360000000000002e-05"/><inertia ixx="8.7002718e-03" ixy="-4.7576583e-05" ixz="1.1160499e-04" iyy="8.6195418e-03" iyz="-3.5422299e-06" izz="1.4612727e-02"/></inertial></link><gazebo reference="back_right_wheel"><mu1 value="1.0"/><mu2 value="1.0"/><!--kp  value="10000.0" />
    <kd  value="1.0" />
    <fdir1 value="1 0 0"/--><material>Gazebo/Grey</material><turnGravityOff>false</turnGravityOff></gazebo><joint name="back_right_wheel_joint" type="continuous"><parent link="base_link"/><child link="back_right_wheel"/><origin rpy="0 0 0" xyz="-0.078 -0.08499999999999999 -0.045"/><axis rpy="0 0 0" xyz="0 1 0"/><limit effort="1000" velocity="1000"/><joint_properties damping="0.0" friction="0.0"/></joint><!-- LEFT WHEEL --><link name="back_left_wheel"><visual><origin rpy="0 1.5707963267948966 1.5707963267948966" xyz="0 0 0"/><geometry><cylinder length="0.025" radius="0.032"/></geometry><material name="DarkGray"/></visual><collision><origin rpy="0 1.5707963267948966 1.5707963267948966" xyz="0 0 0"/><geometry><cylinder length="0.025" radius="0.032"/></geometry></collision><inertial><mass value="0.03"/><origin rpy="0 1.5707963267948966 1.5707963267948966" xyz="0 0 0"/><inertia ixx="9.2425e-06" ixy="0" ixz="0" iyy="9.2425e-06" iyz="0" izz="1.5360000000000002e-05"/></inertial></link><gazebo reference="back_left_wheel"><mu1 value="1.0"/><mu2 value="1.0"/><!--kp  value="10000.0" />
    <kd  value="1.0" />
    <fdir1 value="1 0 0"/--><material>Gazebo/Grey</material><turnGravityOff>false</turnGravityOff></gazebo><joint name="back_left_wheel_joint" type="continuous"><parent link="base_link"/><child link="back_left_wheel"/><origin rpy="0 0 0" xyz="-0.078 0.08499999999999999 -0.045"/><axis rpy="0 0 0" xyz="0 1 0"/><limit effort="100" velocity="100"/><joint_properties damping="0.0" friction="0.0"/></joint><gazebo><!-- differential drive controller (for two wheels) --><plugin filename="libgazebo_ros_diff_drive.so" name="differential_drive_controller"><robotNamespace></robotNamespace><updateRate>30</updateRate><left_joint>back_left_wheel_joint</left_joint><right_joint>back_right_wheel_joint</right_joint><wheel_separation>0.35</wheel_separation><wheel_diameter>0.1</wheel_diameter><wheelAcceleration>1.8</wheelAcceleration><wheelTorque>200</wheelTorque><commandTopic>cmd_vel</commandTopic><odometryTopic>odom</odometryTopic><odometry_frame>odom</odometry_frame><robot_base_frame>base_link</robot_base_frame><!-- Odometry source, 0 for ENCODER, 1 for WORLD, defaults to WORLD --><odometrySource>world</odometrySource><publishWheelTF>false</publishWheelTF><publish_odom>true</publish_odom><publish_odom_tf>true</publish_odom_tf><publish_wheel_tf>true</publish_wheel_tf><publishTF>false</publishTF><publishWheelJointState>false</publishWheelJointState><legacyMode>false</legacyMode><robotBaseFrame>base_footprint</robotBaseFrame><rosDebugLevel>na</rosDebugLevel></plugin></gazebo><!--fb : front, back ; lr: left, right --><!-- ydlidar laser sensor --><link name="ydlidar_link"><collision><origin rpy="0 0 0" xyz="0 0 0"/><geometry><cylinder length="0.055" radius="0.033"/></geometry></collision><visual><origin rpy="0 0 0" xyz="0 0 0"/><geometry><cylinder length="0.055" radius="0.033"/></geometry><material name="Blue"/></visual></link><gazebo reference="ydlidar_link"><material>Gazebo/Blue</material><turnGravityOff>false</turnGravityOff><sensor name="head_ydlidar_sensor" type="ray"><pose>0 0 0.0175 0 0</pose><visualize>False</visualize><update_rate>8.3</update_rate><ray><scan><horizontal><samples>7</samples><resolution>1</resolution><min_angle>-0.3</min_angle><max_angle>0.3</max_angle></horizontal></scan><range><min>0.10</min><max>2.0</max><resolution>0.01</resolution></range><noise><type>gaussian</type><mean>0.0</mean><stddev>0.01</stddev></noise></ray><plugin filename="libgazebo_ros_ray_sensor.so" name="scan"><topicName>scan</topicName><frameName>ydlidar_link</frameName><output_type>sensor_msgs/LaserScan</output_type></plugin></sensor></gazebo><joint name="ydlidar_joint" type="fixed"><origin rpy="0 0 0" xyz="0 0 0.0725"/><parent link="base_link"/><child link="ydlidar_link"/></joint></robot>
